(dp1
S'output'
p2
S'<type \'exceptions.RuntimeError\'> Failure to connect, tried 5 times:\nTraceback (most recent call last):\n  File "/home/nalini/Desktop/web2py/gluon/dal.py", line 7845, in __init__\n    self._adapter = ADAPTERS[self._dbname](**kwargs)\n  File "/home/nalini/Desktop/web2py/gluon/dal.py", line 688, in __call__\n    obj = super(AdapterMeta, cls).__call__(*args, **kwargs)\n  File "/home/nalini/Desktop/web2py/gluon/dal.py", line 2728, in __init__\n    if do_connect: self.reconnect()\n  File "/home/nalini/Desktop/web2py/gluon/dal.py", line 648, in reconnect\n    self.connection = f()\n  File "/home/nalini/Desktop/web2py/gluon/dal.py", line 2726, in connector\n    return self.driver.connect(**driver_args)\n  File "/usr/lib/python2.7/dist-packages/MySQLdb/__init__.py", line 81, in Connect\n    return Connection(*args, **kwargs)\n  File "/usr/lib/python2.7/dist-packages/MySQLdb/connections.py", line 187, in __init__\n    super(Connection, self).__init__(*args, **kwargs2)\nOperationalError: (1049, "Unknown database \'database2\'")\n'
p3
sS'layer'
p4
S'/home/nalini/Desktop/web2py/applications/MYBAZAAR/models/db.py'
p5
sS'code'
p6
S"db = DAL('mysql://root:baadal@localhost/database2')\n    \nfrom gluon.tools import Auth, Crud, Service, PluginManager, prettydate\nauth = Auth(db)\ncrud, service, plugins = Crud(db), Service(), PluginManager()\n\n## configure email\nmail = auth.settings.mailer\nmail.settings.server = 'logging' or 'smtp.gmail.com:587'\nmail.settings.sender = 'you@gmail.com'\nmail.settings.login = 'username:password'\n\n## configure auth policy\nauth.settings.registration_requires_verification = False\nauth.settings.registration_requires_approval = False\nauth.settings.reset_password_requires_verification = False\nauth.define_tables(username=True, signature=False)\nauth.settings.registration_requires_approval = False\nauth.settings.actions_disabled=['change_password','request_reset_password','profile','forgot_username','retrieve_username','remember']\n\n##from gluon.contrib.login_methods.basic_auth import basic_auth\n##auth.settings.login_methods.append(  basic_auth('https://basic.example.com'))\n##from gluon.contrib.login_methods.rpx_account import use_janrain\n##use_janrain(auth, filename='private/janrain.key')\n\nfrom gluon.contrib.login_methods.pam_auth import pam_auth\nauth.settings.login_methods=[pam_auth()]\n\ndb.define_table('requests' , \nField('user_id','integer'),\nField('email_id','string'),\nField('phone_no','integer'),\nField('category','string'),\nField('sub_category' , 'string'),\nField('item_name','string'),\nField('description','string'),\nField('price','integer'),\nField('purpose','string'))\n\ndb.define_table('orders' ,\nField('user_id','integer'),\nField('category','string'),\nField('sub_category','string'),\nField('item_name','string') ,\nField('buyer_name','string'),\nField('email_id','string'),\nField('phone_no','integer'))\n"
p7
sS'snapshot'
p8
(dp9
sS'traceback'
p10
S'Traceback (most recent call last):\n  File "/home/nalini/Desktop/web2py/gluon/restricted.py", line 217, in restricted\n    exec ccode in environment\n  File "/home/nalini/Desktop/web2py/applications/MYBAZAAR/models/db.py", line 1, in <module>\n    db = DAL(\'mysql://root:baadal@localhost/database2\')\n  File "/home/nalini/Desktop/web2py/gluon/dal.py", line 7867, in __init__\n    raise RuntimeError("Failure to connect, tried %d times:\\n%s" % (attempts, tb))\nRuntimeError: Failure to connect, tried 5 times:\nTraceback (most recent call last):\n  File "/home/nalini/Desktop/web2py/gluon/dal.py", line 7845, in __init__\n    self._adapter = ADAPTERS[self._dbname](**kwargs)\n  File "/home/nalini/Desktop/web2py/gluon/dal.py", line 688, in __call__\n    obj = super(AdapterMeta, cls).__call__(*args, **kwargs)\n  File "/home/nalini/Desktop/web2py/gluon/dal.py", line 2728, in __init__\n    if do_connect: self.reconnect()\n  File "/home/nalini/Desktop/web2py/gluon/dal.py", line 648, in reconnect\n    self.connection = f()\n  File "/home/nalini/Desktop/web2py/gluon/dal.py", line 2726, in connector\n    return self.driver.connect(**driver_args)\n  File "/usr/lib/python2.7/dist-packages/MySQLdb/__init__.py", line 81, in Connect\n    return Connection(*args, **kwargs)\n  File "/usr/lib/python2.7/dist-packages/MySQLdb/connections.py", line 187, in __init__\n    super(Connection, self).__init__(*args, **kwargs2)\nOperationalError: (1049, "Unknown database \'database2\'")\n\n'
p11
s.